Workbook
Name Fact_CPI: All_India_Index_Upto_April233[]

Sheet DASHBOARD
AA4: Food&Beverage Share | AB4: =GETPIVOTDATA("Index_Value_Filled",Q1_Bucket_Contribution!$A$3,"Sector","Rural+Urban","Buckets","Food & Beverages") -> 0.51728497
AA5: Peak Inflation Year | AB5: ='Q2)YoY_Inflation_2017_onwards'!P51 -> 2022
AA6: COVID Impact — Health | AB6: ="+"&TEXT(Q4_COVID_Impact!K6-Q4_COVID_Impact!K5,"0.00")&" pp" -> +0.09 pp
AA7: HIGHEST FOOD MONTH | AB7: =_xlfn.XLOOKUP(MAX('Q3_Food_Inflation_(A)'!$C$2:$C$14),'Q3_Food_Inflation_(A)'!$C$2:$C$14,'Q3_Food_Inflation_(A)'!$A$2:$A$14) -> 44713
AA8: OIL CORRELATION | AB8: ="r = "&TEXT(Q5_Oil_Price!E38,"0.00") -> r = -0.48

Sheet Fact_CPI 
A1: Sector | B1: Category | C1: Index_Value | D1: Date | E1: Index_Value_Filled | F1: Buckets
A2: Rural | B2: Cereals and products | C2: 107.5 | D2: 41275 | E2: {=IF(AND(B2="Housing",A2="Rural"),"", _xlfn.IFS( NOT(ISBLANK(C2)), C2, AND(NOT(ISBLANK(C1)), B1=B2, NOT(ISBLANK(C3)), B3=B2), AVERAGE(C1,C3), AND(NOT(ISBLANK(C1)), B1=B2, ISBLANK(C3), NOT(ISBLANK(C4)), B4=B2), C1+(C4-C1)/3, AND(ISBLANK(C1), NOT(ISBLANK(#REF!)),#REF!= B2, NOT(ISBLANK(C3)), B3=B2),#REF!+( C3-#REF!)*2/3, TRUE, "Check Manually" ))} -> 107.5 | F2: =_xlfn.XLOOKUP(B2,Bucket_Map!A:A,Bucket_Map!B:B,"ERROR - CHECK NAME") -> Food & Beverages
A3: Rural | B3: Cereals and products | C3: 109.2 | D3: 41306 | E3: {=IF(AND(B3="Housing",A3="Rural"),"", _xlfn.IFS( NOT(ISBLANK(C3)), C3, AND(NOT(ISBLANK(C2)), B2=B3, NOT(ISBLANK(C4)), B4=B3), AVERAGE(C2,C4), AND(NOT(ISBLANK(C2)), B2=B3, ISBLANK(C4), NOT(ISBLANK(C5)), B5=B3), C2+(C5-C2)/3, AND(ISBLANK(C2), NOT(ISBLANK(C1)), B1=B3, NOT(ISBLANK(C4)), B4=B3), C1+(C4-C1)*2/3, TRUE, "Check Manually" ))} -> 109.2 | F3: =_xlfn.XLOOKUP(B3,Bucket_Map!A:A,Bucket_Map!B:B,"ERROR - CHECK NAME") -> Food & Beverages
A4: Rural | B4: Cereals and products | C4: 110.2 | D4: 41334 | E4: {=IF(AND(B4="Housing",A4="Rural"),"", _xlfn.IFS( NOT(ISBLANK(C4)), C4, AND(NOT(ISBLANK(C3)), B3=B4, NOT(ISBLANK(C5)), B5=B4), AVERAGE(C3,C5), AND(NOT(ISBLANK(C3)), B3=B4, ISBLANK(C5), NOT(ISBLANK(C6)), B6=B4), C3+(C6-C3)/3, AND(ISBLANK(C3), NOT(ISBLANK(C2)), B2=B4, NOT(ISBLANK(C5)), B5=B4), C2+(C5-C2)*2/3, TRUE, "Check Manually" ))} -> 110.2 | F4: =_xlfn.XLOOKUP(B4,Bucket_Map!A:A,Bucket_Map!B:B,"ERROR - CHECK NAME") -> Food & Beverages | I4: TOTAL_ROWS | J4: =ROWS(All_India_Index_Upto_April233[]) -> 10044
A5: Rural | B5: Cereals and products | C5: 110.2 | D5: 41365 | E5: {=IF(AND(B5="Housing",A5="Rural"),"", _xlfn.IFS( NOT(ISBLANK(C5)), C5, AND(NOT(ISBLANK(C4)), B4=B5, NOT(ISBLANK(C6)), B6=B5), AVERAGE(C4,C6), AND(NOT(ISBLANK(C4)), B4=B5, ISBLANK(C6), NOT(ISBLANK(C7)), B7=B5), C4+(C7-C4)/3, AND(ISBLANK(C4), NOT(ISBLANK(C3)), B3=B5, NOT(ISBLANK(C6)), B6=B5), C3+(C6-C3)*2/3, TRUE, "Check Manually" ))} -> 110.2 | F5: =_xlfn.XLOOKUP(B5,Bucket_Map!A:A,Bucket_Map!B:B,"ERROR - CHECK NAME") -> Food & Beverages | I5: Index_value_Blanks | J5: =COUNTBLANK(All_India_Index_Upto_April233[Index_Value]) -> 243
A6: Rural | B6: Cereals and products | C6: 110.9 | D6: 41395 | E6: {=IF(AND(B6="Housing",A6="Rural"),"", _xlfn.IFS( NOT(ISBLANK(C6)), C6, AND(NOT(ISBLANK(C5)), B5=B6, NOT(ISBLANK(C7)), B7=B6), AVERAGE(C5,C7), AND(NOT(ISBLANK(C5)), B5=B6, ISBLANK(C7), NOT(ISBLANK(C8)), B8=B6), C5+(C8-C5)/3, AND(ISBLANK(C5), NOT(ISBLANK(C4)), B4=B6, NOT(ISBLANK(C7)), B7=B6), C4+(C7-C4)*2/3, TRUE, "Check Manually" ))} -> 110.9 | F6: =_xlfn.XLOOKUP(B6,Bucket_Map!A:A,Bucket_Map!B:B,"ERROR - CHECK NAME") -> Food & Beverages | I6: Total_Rurals_Count_without_Blanks | J6: =COUNTIFS(All_India_Index_Upto_April233[Sector],"Rural",All_India_Index_Upto_April233[Index_Value],"<>") -> 3185
A7: Rural | B7: Cereals and products | C7: 112.3 | D7: 41426 | E7: {=IF(AND(B7="Housing",A7="Rural"),"", _xlfn.IFS( NOT(ISBLANK(C7)), C7, AND(NOT(ISBLANK(C6)), B6=B7, NOT(ISBLANK(C8)), B8=B7), AVERAGE(C6,C8), AND(NOT(ISBLANK(C6)), B6=B7, ISBLANK(C8), NOT(ISBLANK(C9)), B9=B7), C6+(C9-C6)/3, AND(ISBLANK(C6), NOT(ISBLANK(C5)), B5=B7, NOT(ISBLANK(C8)), B8=B7), C5+(C8-C5)*2/3, TRUE, "Check Manually" ))} -> 112.3 | F7: =_xlfn.XLOOKUP(B7,Bucket_Map!A:A,Bucket_Map!B:B,"ERROR - CHECK NAME") -> Food & Beverages | I7: Total_Urban_Count_without_Blanks | J7: =COUNTIFS(All_India_Index_Upto_April233[Sector],"Urban",All_India_Index_Upto_April233[Index_Value],"<>") -> 3308
A8: Rural | B8: Cereals and products | C8: 113.4 | D8: 41456 | E8: {=IF(AND(B8="Housing",A8="Rural"),"", _xlfn.IFS( NOT(ISBLANK(C8)), C8, AND(NOT(ISBLANK(C7)), B7=B8, NOT(ISBLANK(C9)), B9=B8), AVERAGE(C7,C9), AND(NOT(ISBLANK(C7)), B7=B8, ISBLANK(C9), NOT(ISBLANK(C10)), B10=B8), C7+(C10-C7)/3, AND(ISBLANK(C7), NOT(ISBLANK(C6)), B6=B8, NOT(ISBLANK(C9)), B9=B8), C6+(C9-C6)*2/3, TRUE, "Check Manually" ))} -> 113.4 | F8: =_xlfn.XLOOKUP(B8,Bucket_Map!A:A,Bucket_Map!B:B,"ERROR - CHECK NAME") -> Food & Beverages | I8: Total_Rural+Urban_Count_without_Blanks | J8: =COUNTIFS(All_India_Index_Upto_April233[Sector],"Rural+Urban",All_India_Index_Upto_April233[Index_Value],"<>") -> 3308
A9: Rural | B9: Cereals and products | C9: 114.3 | D9: 41487 | E9: {=IF(AND(B9="Housing",A9="Rural"),"", _xlfn.IFS( NOT(ISBLANK(C9)), C9, AND(NOT(ISBLANK(C8)), B8=B9, NOT(ISBLANK(C10)), B10=B9), AVERAGE(C8,C10), AND(NOT(ISBLANK(C8)), B8=B9, ISBLANK(C10), NOT(ISBLANK(C11)), B11=B9), C8+(C11-C8)/3, AND(ISBLANK(C8), NOT(ISBLANK(C7)), B7=B9, NOT(ISBLANK(C10)), B10=B9), C7+(C10-C7)*2/3, TRUE, "Check Manually" ))} -> 114.3 | F9: =_xlfn.XLOOKUP(B9,Bucket_Map!A:A,Bucket_Map!B:B,"ERROR - CHECK NAME") -> Food & Beverages
A10: Rural | B10: Cereals and products | C10: 115.4 | D10: 41518 | E10: {=IF(AND(B10="Housing",A10="Rural"),"", _xlfn.IFS( NOT(ISBLANK(C10)), C10, AND(NOT(ISBLANK(C9)), B9=B10, NOT(ISBLANK(C11)), B11=B10), AVERAGE(C9,C11), AND(NOT(ISBLANK(C9)), B9=B10, ISBLANK(C11), NOT(ISBLANK(C12)), B12=B10), C9+(C12-C9)/3, AND(ISBLANK(C9), NOT(ISBLANK(C8)), B8=B10, NOT(ISBLANK(C11)), B11=B10), C8+(C11-C8)*2/3, TRUE, "Check Manually" ))} -> 115.4 | F10: =_xlfn.XLOOKUP(B10,Bucket_Map!A:A,Bucket_Map!B:B,"ERROR - CHECK NAME") -> Food & Beverages
A11: Rural | B11: Cereals and products | C11: 116.3 | D11: 41548 | E11: {=IF(AND(B11="Housing",A11="Rural"),"", _xlfn.IFS( NOT(ISBLANK(C11)), C11, AND(NOT(ISBLANK(C10)), B10=B11, NOT(ISBLANK(C12)), B12=B11), AVERAGE(C10,C12), AND(NOT(ISBLANK(C10)), B10=B11, ISBLANK(C12), NOT(ISBLANK(C13)), B13=B11), C10+(C13-C10)/3, AND(ISBLANK(C10), NOT(ISBLANK(C9)), B9=B11, NOT(ISBLANK(C12)), B12=B11), C9+(C12-C9)*2/3, TRUE, "Check Manually" ))} -> 116.3 | F11: =_xlfn.XLOOKUP(B11,Bucket_Map!A:A,Bucket_Map!B:B,"ERROR - CHECK NAME") -> Food & Beverages
A12: Rural | B12: Cereals and products | C12: 117.3 | D12: 41579 | E12: {=IF(AND(B12="Housing",A12="Rural"),"", _xlfn.IFS( NOT(ISBLANK(C12)), C12, AND(NOT(ISBLANK(C11)), B11=B12, NOT(ISBLANK(C13)), B13=B12), AVERAGE(C11,C13), AND(NOT(ISBLANK(C11)), B11=B12, ISBLANK(C13), NOT(ISBLANK(C14)), B14=B12), C11+(C14-C11)/3, AND(ISBLANK(C11), NOT(ISBLANK(C10)), B10=B12, NOT(ISBLANK(C13)), B13=B12), C10+(C13-C10)*2/3, TRUE, "Check Manually" ))} -> 117.3 | F12: =_xlfn.XLOOKUP(B12,Bucket_Map!A:A,Bucket_Map!B:B,"ERROR - CHECK NAME") -> Food & Beverages
A13: Rural | B13: Cereals and products | C13: 118.4 | D13: 41609 | E13: {=IF(AND(B13="Housing",A13="Rural"),"", _xlfn.IFS( NOT(ISBLANK(C13)), C13, AND(NOT(ISBLANK(C12)), B12=B13, NOT(ISBLANK(C14)), B14=B13), AVERAGE(C12,C14), AND(NOT(ISBLANK(C12)), B12=B13, ISBLANK(C14), NOT(ISBLANK(C15)), B15=B13), C12+(C15-C12)/3, AND(ISBLANK(C12), NOT(ISBLANK(C11)), B11=B13, NOT(ISBLANK(C14)), B14=B13), C11+(C14-C11)*2/3, TRUE, "Check Manually" ))} -> 118.4 | F13: =_xlfn.XLOOKUP(B13,Bucket_Map!A:A,Bucket_Map!B:B,"ERROR - CHECK NAME") -> Food & Beverages
A14: Rural | B14: Cereals and products | C14: 118.9 | D14: 41640 | E14: {=IF(AND(B14="Housing",A14="Rural"),"", _xlfn.IFS( NOT(ISBLANK(C14)), C14, AND(NOT(ISBLANK(C13)), B13=B14, NOT(ISBLANK(C15)), B15=B14), AVERAGE(C13,C15), AND(NOT(ISBLANK(C13)), B13=B14, ISBLANK(C15), NOT(ISBLANK(C16)), B16=B14), C13+(C16-C13)/3, AND(ISBLANK(C13), NOT(ISBLANK(C12)), B12=B14, NOT(ISBLANK(C15)), B15=B14), C12+(C15-C12)*2/3, TRUE, "Check Manually" ))} -> 118.9 | F14: =_xlfn.XLOOKUP(B14,Bucket_Map!A:A,Bucket_Map!B:B,"ERROR - CHECK NAME") -> Food & Beverages
A15: Rural | B15: Cereals and products | C15: 119.4 | D15: 41671 | E15: {=IF(AND(B15="Housing",A15="Rural"),"", _xlfn.IFS( NOT(ISBLANK(C15)), C15, AND(NOT(ISBLANK(C14)), B14=B15, NOT(ISBLANK(C16)), B16=B15), AVERAGE(C14,C16), AND(NOT(ISBLANK(C14)), B14=B15, ISBLANK(C16), NOT(ISBLANK(C17)), B17=B15), C14+(C17-C14)/3, AND(ISBLANK(C14), NOT(ISBLANK(C13)), B13=B15, NOT(ISBLANK(C16)), B16=B15), C13+(C16-C13)*2/3, TRUE, "Check Manually" ))} -> 119.4 | F15: =_xlfn.XLOOKUP(B15,Bucket_Map!A:A,Bucket_Map!B:B,"ERROR - CHECK NAME") -> Food & Beverages
A16: Rural | B16: Cereals and products | C16: 120.1 | D16: 41699 | E16: {=IF(AND(B16="Housing",A16="Rural"),"", _xlfn.IFS( NOT(ISBLANK(C16)), C16, AND(NOT(ISBLANK(C15)), B15=B16, NOT(ISBLANK(C17)), B17=B16), AVERAGE(C15,C17), AND(NOT(ISBLANK(C15)), B15=B16, ISBLANK(C17), NOT(ISBLANK(C18)), B18=B16), C15+(C18-C15)/3, AND(ISBLANK(C15), NOT(ISBLANK(C14)), B14=B16, NOT(ISBLANK(C17)), B17=B16), C14+(C17-C14)*2/3, TRUE, "Check Manually" ))} -> 120.1 | F16: =_xlfn.XLOOKUP(B16,Bucket_Map!A:A,Bucket_Map!B:B,"ERROR - CHECK NAME") -> Food & Beverages
A17: Rural | B17: Cereals and products | C17: 120.2 | D17: 41730 | E17: {=IF(AND(B17="Housing",A17="Rural"),"", _xlfn.IFS( NOT(ISBLANK(C17)), C17, AND(NOT(ISBLANK(C16)), B16=B17, NOT(ISBLANK(C18)), B18=B17), AVERAGE(C16,C18), AND(NOT(ISBLANK(C16)), B16=B17, ISBLANK(C18), NOT(ISBLANK(C19)), B19=B17), C16+(C19-C16)/3, AND(ISBLANK(C16), NOT(ISBLANK(C15)), B15=B17, NOT(ISBLANK(C18)), B18=B17), C15+(C18-C15)*2/3, TRUE, "Check Manually" ))} -> 120.2 | F17: =_xlfn.XLOOKUP(B17,Bucket_Map!A:A,Bucket_Map!B:B,"ERROR - CHECK NAME") -> Food & Beverages
A18: Rural | B18: Cereals and products | C18: 120.3 | D18: 41760 | E18: {=IF(AND(B18="Housing",A18="Rural"),"", _xlfn.IFS( NOT(ISBLANK(C18)), C18, AND(NOT(ISBLANK(C17)), B17=B18, NOT(ISBLANK(C19)), B19=B18), AVERAGE(C17,C19), AND(NOT(ISBLANK(C17)), B17=B18, ISBLANK(C19), NOT(ISBLANK(C20)), B20=B18), C17+(C20-C17)/3, AND(ISBLANK(C17), NOT(ISBLANK(C16)), B16=B18, NOT(ISBLANK(C19)), B19=B18), C16+(C19-C16)*2/3, TRUE, "Check Manually" ))} -> 120.3 | F18: =_xlfn.XLOOKUP(B18,Bucket_Map!A:A,Bucket_Map!B:B,"ERROR - CHECK NAME") -> Food & Beverages
A19: Rural | B19: Cereals and products | C19: 120.7 | D19: 41791 | E19: {=IF(AND(B19="Housing",A19="Rural"),"", _xlfn.IFS( NOT(ISBLANK(C19)), C19, AND(NOT(ISBLANK(C18)), B18=B19, NOT(ISBLANK(C20)), B20=B19), AVERAGE(C18,C20), AND(NOT(ISBLANK(C18)), B18=B19, ISBLANK(C20), NOT(ISBLANK(C21)), B21=B19), C18+(C21-C18)/3, AND(ISBLANK(C18), NOT(ISBLANK(C17)), B17=B19, NOT(ISBLANK(C20)), B20=B19), C17+(C20-C17)*2/3, TRUE, "Check Manually" ))} -> 120.7 | F19: =_xlfn.XLOOKUP(B19,Bucket_Map!A:A,Bucket_Map!B:B,"ERROR - CHECK NAME") -> Food & Beverages
A20: Rural | B20: Cereals and products | C20: 121.7 | D20: 41821 | E20: {=IF(AND(B20="Housing",A20="Rural"),"", _xlfn.IFS( NOT(ISBLANK(C20)), C20, AND(NOT(ISBLANK(C19)), B19=B20, NOT(ISBLANK(C21)), B21=B20), AVERAGE(C19,C21), AND(NOT(ISBLANK(C19)), B19=B20, ISBLANK(C21), NOT(ISBLANK(C22)), B22=B20), C19+(C22-C19)/3, AND(ISBLANK(C19), NOT(ISBLANK(C18)), B18=B20, NOT(ISBLANK(C21)), B21=B20), C18+(C21-C18)*2/3, TRUE, "Check Manually" ))} -> 121.7 | F20: =_xlfn.XLOOKUP(B20,Bucket_Map!A:A,Bucket_Map!B:B,"ERROR - CHECK NAME") -> Food & Beverages
... A88: Rural | B88: Cereals and products | C88: 147.2 | D88: 43922 | E88: {=IF(AND(B88="Housing",A88="Rural"),"", _xlfn.IFS( NOT(ISBLANK(C88)), C88, AND(NOT(ISBLANK(C87)), B87=B88, NOT(ISBLANK(C89)), B89=B88), AVERAGE(C87,C89), AND(NOT(ISBLANK(C87)), B87=B88, ISBLANK(C89), NOT(ISBLANK(C90)), B90=B88), C87+(C90-C87)/3, AND(ISBLANK(C87), NOT(ISBLANK(C86)), B86=B88, NOT(ISBLANK(C89)), B89=B88), C86+(C89-C86)*2/3, TRUE, "Check Manually" ))} -> 147.2 | F88: =_xlfn.XLOOKUP(B88,Bucket_Map!A:A,Bucket_Map!B:B,"ERROR - CHECK NAME") -> Food & Beverages
A89: Rural | B89: Cereals and products | D89: 43952 | E89: {=IF(AND(B89="Housing",A89="Rural"),"", _xlfn.IFS( NOT(ISBLANK(C89)), C89, AND(NOT(ISBLANK(C88)), B88=B89, NOT(ISBLANK(C90)), B90=B89), AVERAGE(C88,C90), AND(NOT(ISBLANK(C88)), B88=B89, ISBLANK(C90), NOT(ISBLANK(C91)), B91=B89), C88+(C91-C88)/3, AND(ISBLANK(C88), NOT(ISBLANK(C87)), B87=B89, NOT(ISBLANK(C90)), B90=B89), C87+(C90-C87)*2/3, TRUE, "Check Manually" ))} -> 147.7 | F89: =_xlfn.XLOOKUP(B89,Bucket_Map!A:A,Bucket_Map!B:B,"ERROR - CHECK NAME") -> Food & Beverages
A90: Rural | B90: Cereals and products | C90: 148.2 | D90: 43983 | E90: {=IF(AND(B90="Housing",A90="Rural"),"", _xlfn.IFS( NOT(ISBLANK(C90)), C90, AND(NOT(ISBLANK(C89)), B89=B90, NOT(ISBLANK(C91)), B91=B90), AVERAGE(C89,C91), AND(NOT(ISBLANK(C89)), B89=B90, ISBLANK(C91), NOT(ISBLANK(C92)), B92=B90), C89+(C92-C89)/3, AND(ISBLANK(C89), NOT(ISBLANK(C88)), B88=B90, NOT(ISBLANK(C91)), B91=B90), C88+(C91-C88)*2/3, TRUE, "Check Manually" ))} -> 148.2 | F90: =_xlfn.XLOOKUP(B90,Bucket_Map!A:A,Bucket_Map!B:B,"ERROR - CHECK NAME") -> Food & Beverages
A91: Rural | B91: Cereals and products | C91: 148.2 | D91: 44013 | E91: {=IF(AND(B91="Housing",A91="Rural"),"", _xlfn.IFS( NOT(ISBLANK(C91)), C91, AND(NOT(ISBLANK(C90)), B90=B91, NOT(ISBLANK(C92)), B92=B91), AVERAGE(C90,C92), AND(NOT(ISBLANK(C90)), B90=B91, ISBLANK(C92), NOT(ISBLANK(C93)), B93=B91), C90+(C93-C90)/3, AND(ISBLANK(C90), NOT(ISBLANK(C89)), B89=B91, NOT(ISBLANK(C92)), B92=B91), C89+(C92-C89)*2/3, TRUE, "Check Manually" ))} -> 148.2 | F91: =_xlfn.XLOOKUP(B91,Bucket_Map!A:A,Bucket_Map!B:B,"ERROR - CHECK NAME") -> Food & Beverages
A92: Rural | B92: Cereals and products | C92: 147.6 | D92: 44044 | E92: {=IF(AND(B92="Housing",A92="Rural"),"", _xlfn.IFS( NOT(ISBLANK(C92)), C92, AND(NOT(ISBLANK(C91)), B91=B92, NOT(ISBLANK(C93)), B93=B92), AVERAGE(C91,C93), AND(NOT(ISBLANK(C91)), B91=B92, ISBLANK(C93), NOT(ISBLANK(C94)), B94=B92), C91+(C94-C91)/3, AND(ISBLANK(C91), NOT(ISBLANK(C90)), B90=B92, NOT(ISBLANK(C93)), B93=B92), C90+(C93-C90)*2/3, TRUE, "Check Manually" ))} -> 147.6 | F92: =_xlfn.XLOOKUP(B92,Bucket_Map!A:A,Bucket_Map!B:B,"ERROR - CHECK NAME") -> Food & Beverages
A93: Rural | B93: Cereals and products | C93: 146.9 | D93: 44075 | E93: {=IF(AND(B93="Housing",A93="Rural"),"", _xlfn.IFS( NOT(ISBLANK(C93)), C93, AND(NOT(ISBLANK(C92)), B92=B93, NOT(ISBLANK(C94)), B94=B93), AVERAGE(C92,C94), AND(NOT(ISBLANK(C92)), B92=B93, ISBLANK(C94), NOT(ISBLANK(C95)), B95=B93), C92+(C95-C92)/3, AND(ISBLANK(C92), NOT(ISBLANK(C91)), B91=B93, NOT(ISBLANK(C94)), B94=B93), C91+(C94-C91)*2/3, TRUE, "Check Manually" ))} -> 146.9 | F93: =_xlfn.XLOOKUP(B93,Bucket_Map!A:A,Bucket_Map!B:B,"ERROR - CHECK NAME") -> Food & Beverages
A94: Rural | B94: Cereals and products | C94: 146 | D94: 44105 | E94: {=IF(AND(B94="Housing",A94="Rural"),"", _xlfn.IFS( NOT(ISBLANK(C94)), C94, AND(NOT(ISBLANK(C93)), B93=B94, NOT(ISBLANK(C95)), B95=B94), AVERAGE(C93,C95), AND(NOT(ISBLANK(C93)), B93=B94, ISBLANK(C95), NOT(ISBLANK(C96)), B96=B94), C93+(C96-C93)/3, AND(ISBLANK(C93), NOT(ISBLANK(C92)), B92=B94, NOT(ISBLANK(C95)), B95=B94), C92+(C95-C92)*2/3, TRUE, "Check Manually" ))} -> 146 | F94: =_xlfn.XLOOKUP(B94,Bucket_Map!A:A,Bucket_Map!B:B,"ERROR - CHECK NAME") -> Food & Beverages
A95: Rural | B95: Cereals and products | C95: 145.4 | D95: 44136 | E95: {=IF(AND(B95="Housing",A95="Rural"),"", _xlfn.IFS( NOT(ISBLANK(C95)), C95, AND(NOT(ISBLANK(C94)), B94=B95, NOT(ISBLANK(C96)), B96=B95), AVERAGE(C94,C96), AND(NOT(ISBLANK(C94)), B94=B95, ISBLANK(C96), NOT(ISBLANK(C97)), B97=B95), C94+(C97-C94)/3, AND(ISBLANK(C94), NOT(ISBLANK(C93)), B93=B95, NOT(ISBLANK(C96)), B96=B95), C93+(C96-C93)*2/3, TRUE, "Check Manually" ))} -> 145.4 | F95: =_xlfn.XLOOKUP(B95,Bucket_Map!A:A,Bucket_Map!B:B,"ERROR - CHECK NAME") -> Food & Beverages
A96: Rural | B96: Cereals and products | C96: 144.6 | D96: 44166 | E96: {=IF(AND(B96="Housing",A96="Rural"),"", _xlfn.IFS( NOT(ISBLANK(C96)), C96, AND(NOT(ISBLANK(C95)), B95=B96, NOT(ISBLANK(C97)), B97=B96), AVERAGE(C95,C97), AND(NOT(ISBLANK(C95)), B95=B96, ISBLANK(C97), NOT(ISBLANK(C98)), B98=B96), C95+(C98-C95)/3, AND(ISBLANK(C95), NOT(ISBLANK(C94)), B94=B96, NOT(ISBLANK(C97)), B97=B96), C94+(C97-C94)*2/3, TRUE, "Check Manually" ))} -> 144.6 | F96: =_xlfn.XLOOKUP(B96,Bucket_Map!A:A,Bucket_Map!B:B,"ERROR - CHECK NAME") -> Food & Beverages
A97: Rural | B97: Cereals and products | C97: 143.4 | D97: 44197 | E97: {=IF(AND(B97="Housing",A97="Rural"),"", _xlfn.IFS( NOT(ISBLANK(C97)), C97, AND(NOT(ISBLANK(C96)), B96=B97, NOT(ISBLANK(C98)), B98=B97), AVERAGE(C96,C98), AND(NOT(ISBLANK(C96)), B96=B97, ISBLANK(C98), NOT(ISBLANK(C99)), B99=B97), C96+(C99-C96)/3, AND(ISBLANK(C96), NOT(ISBLANK(C95)), B95=B97, NOT(ISBLANK(C98)), B98=B97), C95+(C98-C95)*2/3, TRUE, "Check Manually" ))} -> 143.4 | F97: =_xlfn.XLOOKUP(B97,Bucket_Map!A:A,Bucket_Map!B:B,"ERROR - CHECK NAME") -> Food & Beverages
A98: Rural | B98: Cereals and products | C98: 142.8 | D98: 44228 | E98: {=IF(AND(B98="Housing",A98="Rural"),"", _xlfn.IFS( NOT(ISBLANK(C98)), C98, AND(NOT(ISBLANK(C97)), B97=B98, NOT(ISBLANK(C99)), B99=B98), AVERAGE(C97,C99), AND(NOT(ISBLANK(C97)), B97=B98, ISBLANK(C99), NOT(ISBLANK(C100)), B100=B98), C97+(C100-C97)/3, AND(ISBLANK(C97), NOT(ISBLANK(C96)), B96=B98, NOT(ISBLANK(C99)), B99=B98), C96+(C99-C96)*2/3, TRUE, "Check Manually" ))} -> 142.8 | F98: =_xlfn.XLOOKUP(B98,Bucket_Map!A:A,Bucket_Map!B:B,"ERROR - CHECK NAME") -> Food & Beverages
A99: Rural | B99: Cereals and products | C99: 142.5 | D99: 44256 | E99: {=IF(AND(B99="Housing",A99="Rural"),"", _xlfn.IFS( NOT(ISBLANK(C99)), C99, AND(NOT(ISBLANK(C98)), B98=B99, NOT(ISBLANK(C100)), B100=B99), AVERAGE(C98,C100), AND(NOT(ISBLANK(C98)), B98=B99, ISBLANK(C100), NOT(ISBLANK(C101)), B101=B99), C98+(C101-C98)/3, AND(ISBLANK(C98), NOT(ISBLANK(C97)), B97=B99, NOT(ISBLANK(C100)), B100=B99), C97+(C100-C97)*2/3, TRUE, "Check Manually" ))} -> 142.5 | F99: =_xlfn.XLOOKUP(B99,Bucket_Map!A:A,Bucket_Map!B:B,"ERROR - CHECK NAME") -> Food & Beverages
A100: Rural | B100: Cereals and products | C100: 142.7 | D100: 44287 | E100: {=IF(AND(B100="Housing",A100="Rural"),"", _xlfn.IFS( NOT(ISBLANK(C100)), C100, AND(NOT(ISBLANK(C99)), B99=B100, NOT(ISBLANK(C101)), B101=B100), AVERAGE(C99,C101), AND(NOT(ISBLANK(C99)), B99=B100, ISBLANK(C101), NOT(ISBLANK(C102)), B102=B100), C99+(C102-C99)/3, AND(ISBLANK(C99), NOT(ISBLANK(C98)), B98=B100, NOT(ISBLANK(C101)), B101=B100), C98+(C101-C98)*2/3, TRUE, "Check Manually" ))} -> 142.7 | F100: =_xlfn.XLOOKUP(B100,Bucket_Map!A:A,Bucket_Map!B:B,"ERROR - CHECK NAME") -> Food & Beverages
A101: Rural | B101: Cereals and products | C101: 145.1 | D101: 44317 | E101: {=IF(AND(B101="Housing",A101="Rural"),"", _xlfn.IFS( NOT(ISBLANK(C101)), C101, AND(NOT(ISBLANK(C100)), B100=B101, NOT(ISBLANK(C102)), B102=B101), AVERAGE(C100,C102), AND(NOT(ISBLANK(C100)), B100=B101, ISBLANK(C102), NOT(ISBLANK(C103)), B103=B101), C100+(C103-C100)/3, AND(ISBLANK(C100), NOT(ISBLANK(C99)), B99=B101, NOT(ISBLANK(C102)), B102=B101), C99+(C102-C99)*2/3, TRUE, "Check Manually" ))} -> 145.1 | F101: =_xlfn.XLOOKUP(B101,Bucket_Map!A:A,Bucket_Map!B:B,"ERROR - CHECK NAME") -> Food & Beverages
... A211: Rural | B211: Clothing | C211: 153.4 | D211: 43891 | E211: {=IF(AND(B211="Housing",A211="Rural"),"", _xlfn.IFS( NOT(ISBLANK(C211)), C211, AND(NOT(ISBLANK(C210)), B210=B211, NOT(ISBLANK(C212)), B212=B211), AVERAGE(C210,C212), AND(NOT(ISBLANK(C210)), B210=B211, ISBLANK(C212), NOT(ISBLANK(C213)), B213=B211), C210+(C213-C210)/3, AND(ISBLANK(C210), NOT(ISBLANK(C209)), B209=B211, NOT(ISBLANK(C212)), B212=B211), C209+(C212-C209)*2/3, TRUE, "Check Manually" ))} -> 153.4 | F211: =_xlfn.XLOOKUP(B211,Bucket_Map!A:A,Bucket_Map!B:B,"ERROR - CHECK NAME") -> Clothing & Footwear
A212: Rural | B212: Clothing | D212: 43922 | E212: {=IF(AND(B212="Housing",A212="Rural"),"", _xlfn.IFS( NOT(ISBLANK(C212)), C212, AND(NOT(ISBLANK(C211)), B211=B212, NOT(ISBLANK(C213)), B213=B212), AVERAGE(C211,C213), AND(NOT(ISBLANK(C211)), B211=B212, ISBLANK(C213), NOT(ISBLANK(C214)), B214=B212), C211+(C214-C211)/3, AND(ISBLANK(C211), NOT(ISBLANK(C210)), B210=B212, NOT(ISBLANK(C213)), B213=B212), C210+(C213-C210)*2/3, TRUE, "Check Manually" ))} -> 153.83333 | F212: =_xlfn.XLOOKUP(B212,Bucket_Map!A:A,Bucket_Map!B:B,"ERROR - CHECK NAME") -> Clothing & Footwear
A213: Rural | B213: Clothing | D213: 43952 | E213: {=IF(AND(B213="Housing",A213="Rural"),"", _xlfn.IFS( NOT(ISBLANK(C213)), C213, AND(NOT(ISBLANK(C212)), B212=B213, NOT(ISBLANK(C214)), B214=B213), AVERAGE(C212,C214), AND(NOT(ISBLANK(C212)), B212=B213, ISBLANK(C214), NOT(ISBLANK(C215)), B215=B213), C212+(C215-C212)/3, AND(ISBLANK(C212), NOT(ISBLANK(C211)), B211=B213, NOT(ISBLANK(C214)), B214=B213), C211+(C214-C211)*2/3, TRUE, "Check Manually" ))} -> 154.26667 | F213: =_xlfn.XLOOKUP(B213,Bucket_Map!A:A,Bucket_Map!B:B,"ERROR - CHECK NAME") -> Clothing & Footwear
A214: Rural | B214: Clothing | C214: 154.7 | D214: 43983 | E214: {=IF(AND(B214="Housing",A214="Rural"),"", _xlfn.IFS( NOT(ISBLANK(C214)), C214, AND(NOT(ISBLANK(C213)), B213=B214, NOT(ISBLANK(C215)), B215=B214), AVERAGE(C213,C215), AND(NOT(ISBLANK(C213)), B213=B214, ISBLANK(C215), NOT(ISBLANK(C216)), B216=B214), C213+(C216-C213)/3, AND(ISBLANK(C213), NOT(ISBLANK(C212)), B212=B214, NOT(ISBLANK(C215)), B215=B214), C212+(C215-C212)*2/3, TRUE, "Check Manually" ))} -> 154.7 | F214: =_xlfn.XLOOKUP(B214,Bucket_Map!A:A,Bucket_Map!B:B,"ERROR - CHECK NAME") -> Clothing & Footwear
A215: Rural | B215: Clothing | C215: 154.7 | D215: 44013 | E215: {=IF(AND(B215="Housing",A215="Rural"),"", _xlfn.IFS( NOT(ISBLANK(C215)), C215, AND(NOT(ISBLANK(C214)), B214=B215, NOT(ISBLANK(C216)), B216=B215), AVERAGE(C214,C216), AND(NOT(ISBLANK(C214)), B214=B215, ISBLANK(C216), NOT(ISBLANK(C217)), B217=B215), C214+(C217-C214)/3, AND(ISBLANK(C214), NOT(ISBLANK(C213)), B213=B215, NOT(ISBLANK(C216)), B216=B215), C213+(C216-C213)*2/3, TRUE, "Check Manually" ))} -> 154.7 | F215: =_xlfn.XLOOKUP(B215,Bucket_Map!A:A,Bucket_Map!B:B,"ERROR - CHECK NAME") -> Clothing & Footwear
A216: Rural | B216: Clothing | C216: 155.1 | D216: 44044 | E216: {=IF(AND(B216="Housing",A216="Rural"),"", _xlfn.IFS( NOT(ISBLANK(C216)), C216, AND(NOT(ISBLANK(C215)), B215=B216, NOT(ISBLANK(C217)), B217=B216), AVERAGE(C215,C217), AND(NOT(ISBLANK(C215)), B215=B216, ISBLANK(C217), NOT(ISBLANK(C218)), B218=B216), C215+(C218-C215)/3, AND(ISBLANK(C215), NOT(ISBLANK(C214)), B214=B216, NOT(ISBLANK(C217)), B217=B216), C214+(C217-C214)*2/3, TRUE, "Check Manually" ))} -> 155.1 | F216: =_xlfn.XLOOKUP(B216,Bucket_Map!A:A,Bucket_Map!B:B,"ERROR - CHECK NAME") -> Clothing & Footwear
...

Sheet Bucket_Map
A1: Category | B1: Bucket
A2: Cereals and products | B2: Food & Beverages
A3: Clothing | B3: Clothing & Footwear
A4: Clothing and footwear | B4: Not Bucketed (Aggregate)
A5: Education | B5: Education
A6: Egg | B6: Food & Beverages
A7: Food and beverages | B7: Not Bucketed (Aggregate)
A8: Footwear | B8: Clothing & Footwear
A9: Fruits | B9: Food & Beverages
A10: Fuel and light | B10: Fuel & Light
A11: General index | B11: Not Bucketed (Aggregate)
A12: Health | B12: Health
... A28: Vegetables | B28: Food & Beverages

Sheet Q1_Bucket_Contribution
A1: Date | B1: 45047
A3: Sum of Index_Value_Filled | B3: Column Labels
A4: Row Labels | B4: Rural | C4: Rural+Urban | D4: Urban | E4: Grand Total
A5: Food & Beverages | B5: 0.53493433 | C5: 0.51728497 | D5: 0.5239962 | E5: 0.52527933
A6: Clothing & Footwear | B6: 0.095933396 | C6: 0.089220596 | D6: 0.085076335 | E6: 0.090001643
A7: Pan, Tobacco & Intoxicants | B7: 0.050585824 | C7: 0.048864686 | D7: 0.049721201 | E7: 0.049712455
A8: Health | B8: 0.04752385 | C8: 0.045145135 | D8: 0.044364362 | E8: 0.04565396
A9: Personal Care & Effects | B9: 0.046789989 | C9: 0.045023581 | D9: 0.045192237 | E9: 0.04565396
A10: Fuel & Light | B10: 0.046182656 | C10: 0.044440123 | D10: 0.044656554 | E10: 0.04507887
A11: Education | B11: 0.045625933 | C11: 0.043054408 | D11: 0.042562517 | E11: 0.043723299
A12: Household Goods & Services | B12: 0.045499405 | C12: 0.042592503 | D12: 0.041418101 | E12: 0.043139993
A13: Recreation & Amusement | B13: 0.043981071 | C13: 0.041620071 | D13: 0.041198958 | E13: 0.042244496
A14: Transport & Communication | B14: 0.042943543 | C14: 0.04006418 | D14: 0.039056222 | E14: 0.040658889
A15: Housing | B15: 0 | C15: 0.042689746 | D15: 0.042757311 | E15: 0.028853105
A16: Grand Total | B16: 1 | C16: 1 | D16: 1 | E16: 1
A36: Sector | B36: Rural+Urban
A37: Date | B37: 45047
A39: Row Labels | B39: Sum of Index_Value_Filled
A40: Clothing & Footwear | B40: 367
A41: Education | B41: 177.1
A42: Food & Beverages | B42: 2127.8
A43: Fuel & Light | B43: 182.8
A44: Health | B44: 185.7
A45: Household Goods & Services | B45: 175.2
A46: Housing | B46: 175.6
A47: Pan, Tobacco & Intoxicants | B47: 201
A48: Personal Care & Effects | B48: 185.2
A49: Recreation & Amusement | B49: 171.2
A50: Transport & Communication | B50: 164.8
A53: Sector | B53: Rural+Urban
A54: Date | B54: 45047
A55: Buckets | B55: Food & Beverages
A57: Row Labels | B57: Sum of Index_Value
A58: Cereals and products | B58: 173.7
A59: Egg | B59: 173.2
A60: Fruits | B60: 172.2
A61: Meat and fish | B61: 214.3
A62: Milk and products | B62: 179.5
A63: Non-alcoholic beverages | B63: 173.4
A64: Oils and fats | B64: 170
...

Sheet Q2)YoY_Inflation_2017_onwards
A1: DATES | B1: GENERAL_INDEX | C1: YoY_Inflation_Pct
A2: 41275 | B2: 104.6
A3: 41306 | B3: 105.3
A4: 41334 | B4: 105.5
A5: 41365 | B5: 106.1
A6: 41395 | B6: 106.9
A7: 41426 | B7: 109.3
A8: 41456 | B8: 111
A9: 41487 | B9: 112.4
A10: 41518 | B10: 113.7
A11: 41548 | B11: 114.8
A12: 41579 | B12: 116.3
A13: 41609 | B13: 114.5
A14: 41640 | B14: 113.6 | C14: 8.6042065
A15: 41671 | B15: 113.6 | C15: 7.8822412
A16: 41699 | B16: 114.2 | C16: 8.2464455
A17: 41730 | B17: 115.1 | C17: 8.4825636
A18: 41760 | B18: 115.8 | C18: 8.3255379
A19: 41791 | B19: 116.7 | C19: 6.7703568
A20: 41821 | B20: 119.2 | C20: 7.3873874
A21: 41852 | B21: 120.3 | C21: 7.0284698
A22: 41883 | B22: 120.1 | C22: 5.6288478
A23: 41913 | B23: 120.1 | C23: 4.6167247
A24: 41944 | B24: 120.1 | C24: 3.2674119
A25: 41974 | B25: 119.4 | C25: 4.279476
... A50: 42736 | B50: 130.3 | C50: 3.1670625
A51: 42767 | B51: 130.6 | C51: 3.6507937 | P51: =_xlfn.XLOOKUP(Q51,Table6[Avg_YoY],Table6[Year]) -> 2022 | Q51: =MAX(Table6[Avg_YoY]) -> 6.624065
A52: 42795 | B52: 130.9 | C52: 3.8888889 | S52: Year | T52: Avg_YoY
A53: 42826 | B53: 131.1 | C53: 2.9850746 | S53: 2017 | T53: =AVERAGEIFS(C:C, A:A, ">="&DATE(2017,1,1), A:A, "<="&DATE(2017,12,31)) -> 3.1864194
A54: 42856 | B54: 131.4 | C54: 2.1772939 | S54: 2018 | T54: =AVERAGEIFS(C:C, A:A, ">="&DATE(2018,1,1), A:A, "<="&DATE(2018,12,31)) -> 3.9676972
A55: 42887 | B55: 132 | C55: 1.4604151 | S55: 2019 | T55: =AVERAGEIFS(C:C, A:A, ">="&DATE(2019,1,1), A:A, "<="&DATE(2019,12,31)) -> 3.972956
A56: 42917 | B56: 134.2 | C56: 2.3646072 | S56: 2020 | T56: =AVERAGEIFS(C:C, A:A, ">="&DATE(2020,1,1), A:A, "<="&DATE(2020,12,31)) -> 6.2683917
A57: 42948 | B57: 135.4 | C57: 3.279939 | S57: 2021 | T57: =AVERAGEIFS(C:C, A:A, ">="&DATE(2021,1,1), A:A, "<="&DATE(2021,12,31)) -> 5.6349619
A58: 42979 | B58: 135.2 | C58: 3.2849503 | S58: 2022 | T58: =AVERAGEIFS(C:C, A:A, ">="&DATE(2022,1,1), A:A, "<="&DATE(2022,12,31)) -> 6.624065
A59: 43009 | B59: 136.1 | C59: 3.5768645 | S59: 2023 | T59: =AVERAGEIFS(C:C, A:A, ">="&DATE(2023,1,1), A:A, "<="&DATE(2023,12,31)) -> 5.5756722
A60: 43070 | B60: 137.2 | C60: 5.2147239
A61: 43101 | B61: 136.9 | C61: 5.0652341
A62: 43132 | B62: 136.4 | C62: 4.4410413
A63: 43160 | B63: 136.5 | C63: 4.2780749
A64: 43191 | B64: 137.1 | C64: 4.576659
...

Sheet Q3_Food_Inflation_(A)
A1: DATES | B1: GENERAL_INDEX | C1: MoM_Inflation_Pct
A2: 44682 | B2: 13749
A3: 44713 | B3: 13846.7 | C3: =(B3-B2)/B2*100 -> 0.71059713
A4: 44743 | B4: 13906.5 | C4: =(B4-B3)/B3*100 -> 0.43187185
A5: 44774 | B5: 13947 | C5: =(B5-B4)/B4*100 -> 0.29123072
A6: 44805 | B6: 14018.3 | C6: =(B6-B5)/B5*100 -> 0.51122105 | F6: Highest Inflation Month | G6: =_xlfn.XLOOKUP(MAX($C$2:$C$14),$C$2:$C$14,$A$2:$A$14) -> 44713
A7: 44835 | B7: 14103.6 | C7: =(B7-B6)/B6*100 -> 0.60849033 | F7: Lowest Inflation Month | G7: =_xlfn.XLOOKUP(MIN($C$2:$C$14),$C$2:$C$14,$A$2:$A$14) -> 44896
A8: 44866 | B8: 14126.1 | C8: =(B8-B7)/B7*100 -> 0.15953374
A9: 44896 | B9: 14109.8 | C9: =(B9-B8)/B8*100 -> -0.11538924
A10: 44927 | B10: 14174.2 | C10: =(B10-B9)/B9*100 -> 0.45642036
A11: 44958 | B11: 14185 | C11: =(B11-B10)/B10*100 -> 0.076194776
A12: 44986 | B12: 14184.8 | C12: =(B12-B11)/B11*100 -> -0.0014099401
A13: 45017 | B13: 14253.4 | C13: =(B13-B12)/B12*100 -> 0.48361627
A14: 45047 | B14: 14331.2 | C14: =(B14-B13)/B13*100 -> 0.54583468

Sheet Q3_Category_Change
A1: Categories | B1: 44682 | C1: 45047 | D1: Absolute Change
A2: Spices | B2: 184.9 | C2: 218 | D2: 33.1
A3: Cereals and products | B3: 154.1 | C3: 173.7 | D3: 19.6
A4: Milk and products | B4: 164.9 | C4: 179.5 | D4: 14.6
A5: Prepared meals, snacks, sweets etc. | B5: 182.5 | C5: 194.2 | D5: 11.7
A6: Pulses and products | B6: 164.7 | C6: 175.6 | D6: 10.9
A7: Egg | B7: 162.4 | C7: 173.2 | D7: 10.8
A8: Non-alcoholic beverages | B8: 167.1 | C8: 173.4 | D8: 6.3
A9: Sugar and Confectionery | B9: 119.7 | C9: 122.7 | D9: 3
A10: Fruits | B10: 171 | C10: 172.2 | D10: 1.2
A11: Meat and fish | B11: 217 | C11: 214.3 | D11: -2.7
A12: Vegetables | B12: 174.9 | C12: 161 | D12: -13.9
A13: Oils and fats | B13: 202.4 | C13: 170 | D13: -32.4

Sheet Q4_COVID_Impact
A1: Row Labels | B1: Food & Beverages | C1: Health | D1: Household Goods & Services | E1: Food_MoM | F1: Health_MoM | G1: Household_MoM
A2: 41275 | B2: 3804.4 | C2: 312.1 | D2: 314.4
A3: 41306 | B3: 3835.1 | C3: 313.6 | D3: 315.6 | E3: =(B3-B2)/B2*100 -> 0.80696036 | F3: =(C3-C2)/C2*100 -> 0.48061519 | G3: =(D3-D2)/D2*100 -> 0.38167939
A4: 41334 | B4: 3832.2 | C4: 314.8 | D4: 316.9 | E4: =(B4-B3)/B3*100 -> -0.075617324 | F4: =(C4-C3)/C3*100 -> 0.38265306 | G4: =(D4-D3)/D3*100 -> 0.41191381 | J4: Food & Beverages | K4: Health | L4: Household Goods & Services | S4: Food & Beverages | T4: Health | U4: Household Goods & Services
A5: 41365 | B5: 3850.1 | C5: 316.1 | D5: 318.9 | E5: =(B5-B4)/B4*100 -> 0.46709462 | F5: =(C5-C4)/C4*100 -> 0.41296061 | G5: =(D5-D4)/D4*100 -> 0.63111392 | I5: Before (Jan 2013–Feb 2020) | J5: =AVERAGEIFS(E:E, A:A, ">="&DATE(2013,1,1), A:A, "<="&DATE(2020,2,29)) -> 0.39715366 | K5: =AVERAGEIFS(F:F, A:A, ">="&DATE(2013,1,1), A:A, "<="&DATE(2020,2,29)) -> 0.44305489 | L5: =AVERAGEIFS(G:G, A:A, ">="&DATE(2013,1,1), A:A, "<="&DATE(2020,2,29)) -> 0.39734102 | R5: Before (Mar 2019–Feb 2020) | S5: =AVERAGEIFS(E:E, A:A, ">="&DATE(2019,3,1), A:A, "<="&DATE(2020,2,29)) -> 0.77372008 | T5: =AVERAGEIFS(F:F, A:A, ">="&DATE(2019,3,1), A:A, "<="&DATE(2020,2,29)) -> 0.37619767 | U5: =AVERAGEIFS(G:G, A:A, ">="&DATE(2019,3,1), A:A, "<="&DATE(2020,2,29)) -> 0.17178015
A6: 41395 | B6: 3885 | C6: 317.8 | D6: 320.8 | E6: =(B6-B5)/B5*100 -> 0.90646996 | F6: =(C6-C5)/C5*100 -> 0.53780449 | G6: =(D6-D5)/D5*100 -> 0.59579806 | I6: After (Mar 2020–May 2023) | J6: =AVERAGEIFS(E:E, A:A, ">="&DATE(2020,3,1), A:A, "<="&DATE(2023,5,31)) -> 0.49416361 | K6: =AVERAGEIFS(F:F, A:A, ">="&DATE(2020,3,1), A:A, "<="&DATE(2023,5,31)) -> 0.53027107 | L6: =AVERAGEIFS(G:G, A:A, ">="&DATE(2020,3,1), A:A, "<="&DATE(2023,5,31)) -> 0.46336973 | R6: After (Mar 2020–Feb 2021) | S6: =AVERAGEIFS(E:E, A:A, ">="&DATE(2020,3,1), A:A, "<="&DATE(2021,2,28)) -> 0.5795352 | T6: =AVERAGEIFS(F:F, A:A, ">="&DATE(2020,3,1), A:A, "<="&DATE(2021,2,28)) -> 0.53129397 | U6: =AVERAGEIFS(G:G, A:A, ">="&DATE(2020,3,1), A:A, "<="&DATE(2021,2,28)) -> 0.255584
A7: 41426 | B7: 3982.8 | C7: 319.2 | D7: 322.8 | E7: =(B7-B6)/B6*100 -> 2.5173745 | F7: =(C7-C6)/C6*100 -> 0.44052863 | G7: =(D7-D6)/D6*100 -> 0.6234414
A8: 41456 | B8: 4051.4 | C8: 321 | D8: 324.6 | E8: =(B8-B7)/B7*100 -> 1.7224063 | F8: =(C8-C7)/C7*100 -> 0.56390977 | G8: =(D8-D7)/D7*100 -> 0.55762082
A9: 41487 | B9: 4094.9 | C9: 322.6 | D9: 326.1 | E9: =(B9-B8)/B8*100 -> 1.0737029 | F9: =(C9-C8)/C8*100 -> 0.49844237 | G9: =(D9-D8)/D8*100 -> 0.46210721
A10: 41518 | B10: 4125.3 | C10: 324.3 | D10: 328.8 | E10: =(B10-B9)/B9*100 -> 0.74238687 | F10: =(C10-C9)/C9*100 -> 0.52696838 | G10: =(D10-D9)/D9*100 -> 0.82796688
A11: 41548 | B11: 4174.6 | C11: 325.7 | D11: 330.9 | E11: =(B11-B10)/B10*100 -> 1.1950646 | F11: =(C11-C10)/C10*100 -> 0.43169904 | G11: =(D11-D10)/D10*100 -> 0.63868613
A12: 41579 | B12: 4252.2 | C12: 327.6 | D12: 333.3 | E12: =(B12-B11)/B11*100 -> 1.8588607 | F12: =(C12-C11)/C11*100 -> 0.58335892 | G12: =(D12-D11)/D11*100 -> 0.72529465
A13: 41609 | B13: 4165.8 | C13: 328.8 | D13: 335.1 | E13: =(B13-B12)/B12*100 -> -2.0318894 | F13: =(C13-C12)/C12*100 -> 0.36630037 | G13: =(D13-D12)/D12*100 -> 0.54005401
A14: 41640 | B14: 4109.4 | C14: 330.6 | D14: 336.8 | E14: =(B14-B13)/B13*100 -> -1.3538816 | F14: =(C14-C13)/C13*100 -> 0.54744526 | G14: =(D14-D13)/D13*100 -> 0.50731125
A15: 41671 | B15: 4092.5 | C15: 332 | D15: 338.3 | E15: =(B15-B14)/B14*100 -> -0.41125225 | F15: =(C15-C14)/C14*100 -> 0.42347247 | G15: =(D15-D14)/D14*100 -> 0.44536817
A16: 41699 | B16: 4114.4 | C16: 333.4 | D16: 339.6 | E16: =(B16-B15)/B15*100 -> 0.53512523 | F16: =(C16-C15)/C15*100 -> 0.42168675 | G16: =(D16-D15)/D15*100 -> 0.38427431
A17: 41730 | B17: 4159.2 | C17: 334.3 | D17: 340.7 | E17: =(B17-B16)/B16*100 -> 1.0888586 | F17: =(C17-C16)/C16*100 -> 0.26994601 | G17: =(D17-D16)/D16*100 -> 0.32391048
A18: 41760 | B18: 4200.6 | C18: 335.1 | D18: 342.3 | E18: =(B18-B17)/B17*100 -> 0.99538373 | F18: =(C18-C17)/C17*100 -> 0.23930601 | G18: =(D18-D17)/D17*100 -> 0.46962137
... A40: 42430 | B40: 4636.4 | C40: 367.4 | D40: 375.1 | E40: =(B40-B39)/B39*100 -> -0.23883808 | F40: =(C40-C39)/C39*100 -> 0.3003003 | G40: =(D40-D39)/D39*100 -> 0.42838019
A41: 42461 | B41: 4713.8 | C41: 368.4 | D41: 376.3 | E41: =(B41-B40)/B40*100 -> 1.6693987 | F41: =(C41-C40)/C40*100 -> 0.27218291 | G41: =(D41-D40)/D40*100 -> 0.31991469 | I41: ="+"&TEXT('Q4_COVID_Impact'!(After cell)-'Q4_COVID_Impact'!(Before cell),"0.00")&" pp"
A42: 42491 | B42: 4798.7 | C42: 369.8 | D42: 377.7 | E42: =(B42-B41)/B41*100 -> 1.8010947 | F42: =(C42-C41)/C41*100 -> 0.38002172 | G42: =(D42-D41)/D41*100 -> 0.37204358
A43: 42522 | B43: 4885.2 | C43: 370.9 | D43: 378.9 | E43: =(B43-B42)/B42*100 -> 1.8025715 | F43: =(C43-C42)/C42*100 -> 0.29745809 | G43: =(D43-D42)/D42*100 -> 0.31771247
A44: 42552 | B44: 4949.5 | C44: 372.1 | D44: 380.4 | E44: =(B44-B43)/B43*100 -> 1.3162204 | F44: =(C44-C43)/C43*100 -> 0.32353734 | G44: =(D44-D43)/D43*100 -> 0.39588282
A45: 42583 | B45: 4925.9 | C45: 373 | D45: 381.9 | E45: =(B45-B44)/B44*100 -> -0.47681584 | F45: =(C45-C44)/C44*100 -> 0.24187046 | G45: =(D45-D44)/D44*100 -> 0.39432177
A46: 42614 | B46: 4881.3 | C46: 374.6 | D46: 383.3 | E46: =(B46-B45)/B45*100 -> -0.9054183 | F46: =(C46-C45)/C45*100 -> 0.42895442 | G46: =(D46-D45)/D45*100 -> 0.36658811
A47: 42644 | B47: 4890.8 | C47: 376.6 | D47: 384.7 | E47: =(B47-B46)/B46*100 -> 0.19462029 | F47: =(C47-C46)/C46*100 -> 0.53390283 | G47: =(D47-D46)/D46*100 -> 0.36524915
A48: 42675 | B48: 4871.7 | C48: 377.6 | D48: 385.4 | E48: =(B48-B47)/B47*100 -> -0.39052916 | F48: =(C48-C47)/C47*100 -> 0.26553372 | G48: =(D48-D47)/D47*100 -> 0.18195997
A49: 42705 | B49: 4818.1 | C49: 378.9 | D49: 387.1 | E49: =(B49-B48)/B48*100 -> -1.100232 | F49: =(C49-C48)/C48*100 -> 0.34427966 | G49: =(D49-D48)/D48*100 -> 0.44110016
A50: 42736 | B50: 4779 | C50: 379.6 | D50: 387.7 | E50: =(B50-B49)/B49*100 -> -0.81152321 | F50: =(C50-C49)/C49*100 -> 0.18474532 | G50: =(D50-D49)/D49*100 -> 0.15499871
A51: 42767 | B51: 4763.4 | C51: 380.4 | D51: 388.6 | E51: =(B51-B50)/B50*100 -> -0.32642812 | F51: =(C51-C50)/C50*100 -> 0.21074816 | G51: =(D51-D50)/D50*100 -> 0.23213825
A52: 42795 | B52: 4754 | C52: 381.5 | D52: 389.8 | E52: =(B52-B51)/B51*100 -> -0.19733804 | F52: =(C52-C51)/C51*100 -> 0.2891693 | G52: =(D52-D51)/D51*100 -> 0.30880082
A53: 42826 | B53: 4752.4 | C53: 382.5 | D53: 390.7 | E53: =(B53-B52)/B52*100 -> -0.033655869 | F53: =(C53-C52)/C52*100 -> 0.2621232 | G53: =(D53-D52)/D52*100 -> 0.23088763
... A125: 45047 | B125: 6393.7 | C125: 555.7 | D125: 525.1 | E125: =(B125-B124)/B124*100 -> 0.75165459 | F125: =(C125-C124)/C124*100 -> 0.36120643 | G125: =(D125-D124)/D124*100 -> 0.34397095

Sheet Crude-Oil-FOB-Price-(India)
A1: "Source: PPAC (Petroleum Planning & Analysis Cell), Indian Basket crude oil FOB price"
A3: Petroleum Planning & Analysis Cell
A5: Crude Oil FOB Price (Indian Basket)
A7: Table Posted: (02-04-2025)
A8: Period : Since 2000-01
O9: ($/bbl.)
A10: Year | B10: 33329 | C10: 33359 | D10: 33390 | E10: 33420 | F10: 33451 | G10: 33482 | H10: 33512 | I10: 33543 | J10: 33573 | K10: 33604 | L10: 33635 | M10: 33664 | N10: Average | O10: Ratio *
A11: 2000-01 | B11: 22.51 | C11: 26.6 | D11: 28.49 | E11: 27.26 | F11: 28.328849 | G11: 31.34 | H11: 30.5 | I11: 30.926622 | J11: 23.25 | K11: 24.02 | L11: 25.92 | M11: 23.82 | N11: 26.924167 | O11: 57:43
A12: 2001-02 | B12: 24.82 | C12: 26.95 | D12: 26.63 | E12: 23.99 | F12: 25.01 | G12: 24.79 | H12: 20.05 | I12: 18.24 | J12: 18.24 | K12: 18.92 | L12: 19.529987 | M12: 23.31 | N12: 22.551701 | O12: 57:43
A13: 2002-03 | B13: 25.029406 | C13: 24.994865 | D13: 24.051814 | E13: 25.183222 | F13: 25.855818 | G13: 27.495243 | H13: 26.902101 | I13: 23.682512 | J13: 27.110101 | K13: 29.59255 | L13: 31.308381 | M13: 28.825039 | N13: 26.6 | O13: 57:43
A14: 2003-04 | B14: 24.214592 | C14: 24.988879 | D14: 26.425925 | E14: 27.45845 | F14: 28.663599 | G14: 26.265218 | H14: 28.449944 | I14: 28.226284 | J14: 28.966611 | K14: 29.999534 | L14: 29.647267 | M14: 32.210323 | N14: 27.98 | O14: 57:43
A15: 2004-05 | B15: 32.365205 | C15: 36.078851 | D15: 34.159548 | E15: 36.353382 | F15: 40.5172 | G15: 39.149477 | H15: 43.375467 | I15: 38.89887 | J15: 36.816215 | K15: 40.962002 | L15: 42.670599 | M15: 49.27002 | N15: 39.205833 | O15: 57:43
A16: 2005-06 | B16: 49.427602 | C16: 46.995224 | D16: 52.720745 | E16: 55.008083 | F16: 60.048336 | G16: 59.739214 | H16: 56.279062 | I16: 53.143808 | J16: 55.045629 | K16: 60.542917 | L16: 58.95333 | M16: 60.011574 | N16: 55.72 | O16: 58:42
A17: 2006-07 | B17: 67.055031 | C17: 67.223591 | D17: 66.897535 | E17: 71.285795 | F17: 70.775922 | G17: 60.933454 | H17: 57.270685 | I17: 57.793638 | J17: 60.344671 | K17: 52.529441 | L17: 56.531045 | M17: 60.262108 | N17: 62.46 | O17: 59.8:40.2
A18: 2007-08 | B18: 65.481951 | C18: 65.695437 | D18: 68.099251 | E18: 72.575062 | F18: 68.982337 | G18: 74.776604 | H18: 79.327164 | I18: 89.107014 | J18: 87.921265 | K18: 89.517554 | L18: 92.374237 | M18: 99.759819 | N18: 79.249167 | O18: 61.4:38.6
A19: 2008-09 | B19: 105.72015 | C19: 120.90896 | D19: 129.71536 | E19: 132.47125 | F19: 113.05439 | G19: 96.812892 | H19: 69.121527 | I19: 50.907636 | J19: 40.611433 | K19: 43.986058 | L19: 43.217028 | M19: 46.021762 | N19: 83.566667 | O19: 62.3:37.7
A20: 2009-10 | B20: 50.135602 | C20: 58.00336 | D20: 69.115276 | E20: 64.82461 | F20: 71.979192 | G20: 67.70165 | H20: 73.064289 | I20: 77.390866 | J20: 75.016223 | K20: 76.608826 | L20: 73.694278 | M20: 78.0183 | N20: 69.76227 | O20: 63.5:36.5
A21: 2010-11 | B21: 84.081729 | C21: 76.161428 | D21: 74.33109 | E21: 73.543052 | F21: 75.126989 | G21: 76.093 | H21: 81.109814 | I21: 84.255699 | J21: 89.772982 | K21: 93.868448 | L21: 101.621 | M21: 110.71447 | N21: 85.09 | O21: 67.6:32.4
A22: 2011-12 | B22: 118.63579 | C22: 110.80254 | D22: 109.99407 | E22: 112.52711 | F22: 106.93536 | G22: 108.79065 | H22: 106.10837 | I22: 109.61574 | J22: 107.19389 | K22: 110.46828 | L22: 117.6662 | M22: 123.61056 | N22: 111.89 | O22: 65.2:34.8
... A36: 2025-26 | B36: 67.724947 | C36: 64.042044 | D36: 69.77 | E36: 70.95 | F36: 69.11283 | G36: 69.61 | H36: 65.08 | I36: 64.30583 | J36: 62.202431 | K36: 63.083378 | L36: 69.005477 | M36: 113.49 | N36: 70.990726 | O36: 78.71:21.29 (Till Feb'26) & 38.98:61.02 for March'26
A37: Notes:
A38: * The composition of Indian Basket of Crude represents Average of Oman & Dubai for sour grades and Brent (Dated) for sweet grade in the ratio of crude processed during previous financial year, e.g. ratio of crude processed as indicated in the table above.
A39: - Crude oil prices are average of daily prices of respective month.

Sheet Q5_Oil_Price
G1: MoM % Change
A2: Dates | B2: Crude_Oil_Price_USD_bbl | C2: Oil_MoM_Pct | F2: Dates | G2: Clothing | H2: Clothing and footwear | I2: Education | J2: Egg | K2: Footwear | L2: Fruits | M2: Fuel and light | N2: Health | O2: Household goods and services | P2: Housing | Q2: Meat and fish | R2: Milk and products | S2: Non-alcoholic beverages | T2: Oils and fats | U2: Pan, tobacco and intoxicants | V2: Personal care and effects | W2: Prepared meals, snacks, sweets etc. | X2: Pulses and products | Y2: Recreation and amusement | Z2: Spices | AA2: Sugar and Confectionery | AB2: Transport and communication | AC2: Vegetables
A3: 44197 | B3: 54.79457 | F3: 44166
A4: =EDATE(A3,1) -> 44228 | B4: 61.216117 | C4: =(B4-B3)/B3*100 -> 11.719314 | F4: 44197 | G4: =(Q5_CPI_Category_Levels!B3-Q5_CPI_Category_Levels!B2)/Q5_CPI_Category_Levels!B2*100 -> 0.32258065 | H4: =(Q5_CPI_Category_Levels!C3-Q5_CPI_Category_Levels!C2)/Q5_CPI_Category_Levels!C2*100 -> 0.390625 | I4: =(Q5_CPI_Category_Levels!D3-Q5_CPI_Category_Levels!D2)/Q5_CPI_Category_Levels!D2*100 -> -0.12547051 | J4: =(Q5_CPI_Category_Levels!E3-Q5_CPI_Category_Levels!E2)/Q5_CPI_Category_Levels!E2*100 -> 0 | K4: =(Q5_CPI_Category_Levels!F3-Q5_CPI_Category_Levels!F2)/Q5_CPI_Category_Levels!F2*100 -> 0.48143054 | L4: =(Q5_CPI_Category_Levels!G3-Q5_CPI_Category_Levels!G2)/Q5_CPI_Category_Levels!G2*100 -> 1.2863913 | M4: =(Q5_CPI_Category_Levels!H3-Q5_CPI_Category_Levels!H2)/Q5_CPI_Category_Levels!H2*100 -> 2.2821577 | N4: =(Q5_CPI_Category_Levels!I3-Q5_CPI_Category_Levels!I2)/Q5_CPI_Category_Levels!I2*100 -> 0.63171194 | ... AC4: =(Q5_CPI_Category_Levels!X3-Q5_CPI_Category_Levels!X2)/Q5_CPI_Category_Levels!X2*100 -> -15.748373
A5: =EDATE(A4,1) -> 44256 | B5: 64.729497 | C5: =(B5-B4)/B4*100 -> 5.7393047 | F5: 44228 | G5: =(Q5_CPI_Category_Levels!B4-Q5_CPI_Category_Levels!B3)/Q5_CPI_Category_Levels!B3*100 -> 1.0932476 | H5: =(Q5_CPI_Category_Levels!C4-Q5_CPI_Category_Levels!C3)/Q5_CPI_Category_Levels!C3*100 -> 1.0376135 | I5: =(Q5_CPI_Category_Levels!D4-Q5_CPI_Category_Levels!D3)/Q5_CPI_Category_Levels!D3*100 -> 0.18844221 | J5: =(Q5_CPI_Category_Levels!E4-Q5_CPI_Category_Levels!E3)/Q5_CPI_Category_Levels!E3*100 -> -3.7649743 | K5: =(Q5_CPI_Category_Levels!F4-Q5_CPI_Category_Levels!F3)/Q5_CPI_Category_Levels!F3*100 -> 0.88980151 | L5: =(Q5_CPI_Category_Levels!G4-Q5_CPI_Category_Levels!G3)/Q5_CPI_Category_Levels!G3*100 -> 0.73529412 | M5: =(Q5_CPI_Category_Levels!H4-Q5_CPI_Category_Levels!H3)/Q5_CPI_Category_Levels!H3*100 -> 3.0425963 | N5: =(Q5_CPI_Category_Levels!I4-Q5_CPI_Category_Levels!I3)/Q5_CPI_Category_Levels!I3*100 -> 1.2554928 | ... AC5: =(Q5_CPI_Category_Levels!X4-Q5_CPI_Category_Levels!X3)/Q5_CPI_Category_Levels!X3*100 -> -17.610711
A6: =EDATE(A5,1) -> 44287 | B6: 63.396977 | C6: =(B6-B5)/B5*100 -> -2.0585982 | F6: 44256 | G6: =(Q5_CPI_Category_Levels!B5-Q5_CPI_Category_Levels!B4)/Q5_CPI_Category_Levels!B4*100 -> 0.38167939 | H6: =(Q5_CPI_Category_Levels!C5-Q5_CPI_Category_Levels!C4)/Q5_CPI_Category_Levels!C4*100 -> 0.38510911 | I6: =(Q5_CPI_Category_Levels!D5-Q5_CPI_Category_Levels!D4)/Q5_CPI_Category_Levels!D4*100 -> 0.43887147 | J6: =(Q5_CPI_Category_Levels!E5-Q5_CPI_Category_Levels!E4)/Q5_CPI_Category_Levels!E4*100 -> -2.9045643 | K6: =(Q5_CPI_Category_Levels!F5-Q5_CPI_Category_Levels!F4)/Q5_CPI_Category_Levels!F4*100 -> 0.33921303 | L6: =(Q5_CPI_Category_Levels!G5-Q5_CPI_Category_Levels!G4)/Q5_CPI_Category_Levels!G4*100 -> 1.99071 | M6: =(Q5_CPI_Category_Levels!H5-Q5_CPI_Category_Levels!H4)/Q5_CPI_Category_Levels!H4*100 -> 2.0341207 | N6: =(Q5_CPI_Category_Levels!I5-Q5_CPI_Category_Levels!I4)/Q5_CPI_Category_Levels!I4*100 -> 0.24798512 | ... AC6: =(Q5_CPI_Category_Levels!X5-Q5_CPI_Category_Levels!X4)/Q5_CPI_Category_Levels!X4*100 -> -6.5625
A7: =EDATE(A6,1) -> 44317 | B7: 66.953085 | C7: =(B7-B6)/B6*100 -> 5.6092712 | F7: 44287 | G7: =(Q5_CPI_Category_Levels!B6-Q5_CPI_Category_Levels!B5)/Q5_CPI_Category_Levels!B5*100 -> 0.63371356 | H7: =(Q5_CPI_Category_Levels!C6-Q5_CPI_Category_Levels!C5)/Q5_CPI_Category_Levels!C5*100 -> 0.57544757 | I7: =(Q5_CPI_Category_Levels!D6-Q5_CPI_Category_Levels!D5)/Q5_CPI_Category_Levels!D5*100 -> 0.062421973 | J7: =(Q5_CPI_Category_Levels!E6-Q5_CPI_Category_Levels!E5)/Q5_CPI_Category_Levels!E5*100 -> 0.48840049 | K7: =(Q5_CPI_Category_Levels!F6-Q5_CPI_Category_Levels!F5)/Q5_CPI_Category_Levels!F5*100 -> 0.40567951 | L7: =(Q5_CPI_Category_Levels!G6-Q5_CPI_Category_Levels!G5)/Q5_CPI_Category_Levels!G5*100 -> 6.9616135 | M7: =(Q5_CPI_Category_Levels!H6-Q5_CPI_Category_Levels!H5)/Q5_CPI_Category_Levels!H5*100 -> 0.064308682 | N7: =(Q5_CPI_Category_Levels!I6-Q5_CPI_Category_Levels!I5)/Q5_CPI_Category_Levels!I5*100 -> 0.37105751 | ... AC7: =(Q5_CPI_Category_Levels!X6-Q5_CPI_Category_Levels!X5)/Q5_CPI_Category_Levels!X5*100 -> -3.6120401
A8: =EDATE(A7,1) -> 44348 | B8: 71.982647 | C8: =(B8-B7)/B7*100 -> 7.51207 | F8: 44317 | G8: =(Q5_CPI_Category_Levels!B7-Q5_CPI_Category_Levels!B6)/Q5_CPI_Category_Levels!B6*100 -> 1.8891688 | H8: =(Q5_CPI_Category_Levels!C7-Q5_CPI_Category_Levels!C6)/Q5_CPI_Category_Levels!C6*100 -> 1.9707565 | I8: =(Q5_CPI_Category_Levels!D7-Q5_CPI_Category_Levels!D6)/Q5_CPI_Category_Levels!D6*100 -> 0.56144729 | J8: =(Q5_CPI_Category_Levels!E7-Q5_CPI_Category_Levels!E6)/Q5_CPI_Category_Levels!E6*100 -> 3.4629405 | K8: =(Q5_CPI_Category_Levels!F7-Q5_CPI_Category_Levels!F6)/Q5_CPI_Category_Levels!F6*100 -> 2.4242424 | L8: =(Q5_CPI_Category_Levels!G7-Q5_CPI_Category_Levels!G6)/Q5_CPI_Category_Levels!G6*100 -> 1.6423358 | M8: =(Q5_CPI_Category_Levels!H7-Q5_CPI_Category_Levels!H6)/Q5_CPI_Category_Levels!H6*100 -> 2.4421594 | N8: =(Q5_CPI_Category_Levels!I7-Q5_CPI_Category_Levels!I6)/Q5_CPI_Category_Levels!I6*100 -> 2.1565003 | ... AC8: =(Q5_CPI_Category_Levels!X7-Q5_CPI_Category_Levels!X6)/Q5_CPI_Category_Levels!X6*100 -> 2.6370576
A9: =EDATE(A8,1) -> 44378 | B9: 73.539061 | C9: =(B9-B8)/B8*100 -> 2.1622059 | F9: 44348 | G9: =(Q5_CPI_Category_Levels!B8-Q5_CPI_Category_Levels!B7)/Q5_CPI_Category_Levels!B7*100 -> 0.24721879 | H9: =(Q5_CPI_Category_Levels!C8-Q5_CPI_Category_Levels!C7)/Q5_CPI_Category_Levels!C7*100 -> 0.18703242 | I9: =(Q5_CPI_Category_Levels!D8-Q5_CPI_Category_Levels!D7)/Q5_CPI_Category_Levels!D7*100 -> 0.3101737 | J9: =(Q5_CPI_Category_Levels!E8-Q5_CPI_Category_Levels!E7)/Q5_CPI_Category_Levels!E7*100 -> 6.1068702 | K9: =(Q5_CPI_Category_Levels!F8-Q5_CPI_Category_Levels!F7)/Q5_CPI_Category_Levels!F7*100 -> -0.19723866 | L9: =(Q5_CPI_Category_Levels!G8-Q5_CPI_Category_Levels!G7)/Q5_CPI_Category_Levels!G7*100 -> -1.4961101 | M9: =(Q5_CPI_Category_Levels!H8-Q5_CPI_Category_Levels!H7)/Q5_CPI_Category_Levels!H7*100 -> 0.25094103 | N9: =(Q5_CPI_Category_Levels!I8-Q5_CPI_Category_Levels!I7)/Q5_CPI_Category_Levels!I7*100 -> 0.30156815 | ... AC9: =(Q5_CPI_Category_Levels!X8-Q5_CPI_Category_Levels!X7)/Q5_CPI_Category_Levels!X7*100 -> 5.0709939
A10: =EDATE(A9,1) -> 44409 | B10: 69.804724 | C10: =(B10-B9)/B9*100 -> -5.0780307 | F10: 44378 | G10: =(Q5_CPI_Category_Levels!B9-Q5_CPI_Category_Levels!B8)/Q5_CPI_Category_Levels!B8*100 -> 0.36991369 | H10: =(Q5_CPI_Category_Levels!C9-Q5_CPI_Category_Levels!C8)/Q5_CPI_Category_Levels!C8*100 -> 0.43559428 | I10: =(Q5_CPI_Category_Levels!D9-Q5_CPI_Category_Levels!D8)/Q5_CPI_Category_Levels!D8*100 -> 0.92764378 | J10: =(Q5_CPI_Category_Levels!E9-Q5_CPI_Category_Levels!E8)/Q5_CPI_Category_Levels!E8*100 -> 0.83010515 | K10: =(Q5_CPI_Category_Levels!F9-Q5_CPI_Category_Levels!F8)/Q5_CPI_Category_Levels!F8*100 -> 0.85638999 | L10: =(Q5_CPI_Category_Levels!G9-Q5_CPI_Category_Levels!G8)/Q5_CPI_Category_Levels!G8*100 -> -0.42527339 | M10: =(Q5_CPI_Category_Levels!H9-Q5_CPI_Category_Levels!H8)/Q5_CPI_Category_Levels!H8*100 -> 0.56320401 | N10: =(Q5_CPI_Category_Levels!I9-Q5_CPI_Category_Levels!I8)/Q5_CPI_Category_Levels!I8*100 -> 0.42092604 | ... AC10: =(Q5_CPI_Category_Levels!X9-Q5_CPI_Category_Levels!X8)/Q5_CPI_Category_Levels!X8*100 -> 5.6628057
A11: =EDATE(A10,1) -> 44440 | B11: 73.130738 | C11: =(B11-B10)/B10*100 -> 4.7647403 | F11: 44409 | G11: =(Q5_CPI_Category_Levels!B10-Q5_CPI_Category_Levels!B9)/Q5_CPI_Category_Levels!B9*100 -> 1.044226 | H11: =(Q5_CPI_Category_Levels!C10-Q5_CPI_Category_Levels!C9)/Q5_CPI_Category_Levels!C9*100 -> 1.1152416 | I11: =(Q5_CPI_Category_Levels!D10-Q5_CPI_Category_Levels!D9)/Q5_CPI_Category_Levels!D9*100 -> 0.36764706 | J11: =(Q5_CPI_Category_Levels!E10-Q5_CPI_Category_Levels!E9)/Q5_CPI_Category_Levels!E9*100 -> -5.1591658 | K11: =(Q5_CPI_Category_Levels!F10-Q5_CPI_Category_Levels!F9)/Q5_CPI_Category_Levels!F9*100 -> 1.4369693 | L11: =(Q5_CPI_Category_Levels!G10-Q5_CPI_Category_Levels!G9)/Q5_CPI_Category_Levels!G9*100 -> -4.3319097 | M11: =(Q5_CPI_Category_Levels!H10-Q5_CPI_Category_Levels!H9)/Q5_CPI_Category_Levels!H9*100 -> 1.1823273 | N11: =(Q5_CPI_Category_Levels!I10-Q5_CPI_Category_Levels!I9)/Q5_CPI_Category_Levels!I9*100 -> 0.83832335 | ... AC11: =(Q5_CPI_Category_Levels!X10-Q5_CPI_Category_Levels!X9)/Q5_CPI_Category_Levels!X9*100 -> -1.2180268
A12: =EDATE(A11,1) -> 44470 | B12: 82.107394 | C12: =(B12-B11)/B11*100 -> 12.274805 | F12: 44440 | G12: =(Q5_CPI_Category_Levels!B11-Q5_CPI_Category_Levels!B10)/Q5_CPI_Category_Levels!B10*100 -> 0.060790274 | H12: =(Q5_CPI_Category_Levels!C11-Q5_CPI_Category_Levels!C10)/Q5_CPI_Category_Levels!C10*100 -> 0.06127451 | I12: =(Q5_CPI_Category_Levels!D11-Q5_CPI_Category_Levels!D10)/Q5_CPI_Category_Levels!D10*100 -> -0.061050061 | J12: =(Q5_CPI_Category_Levels!E11-Q5_CPI_Category_Levels!E10)/Q5_CPI_Category_Levels!E10*100 -> 0 | K12: =(Q5_CPI_Category_Levels!F11-Q5_CPI_Category_Levels!F10)/Q5_CPI_Category_Levels!F10*100 -> 0 | L12: =(Q5_CPI_Category_Levels!G11-Q5_CPI_Category_Levels!G10)/Q5_CPI_Category_Levels!G10*100 -> -0.06377551 | M12: =(Q5_CPI_Category_Levels!H11-Q5_CPI_Category_Levels!H10)/Q5_CPI_Category_Levels!H10*100 -> 0 | N12: =(Q5_CPI_Category_Levels!I11-Q5_CPI_Category_Levels!I10)/Q5_CPI_Category_Levels!I10*100 -> 0 | ... AC12: =(Q5_CPI_Category_Levels!X11-Q5_CPI_Category_Levels!X10)/Q5_CPI_Category_Levels!X10*100 -> 0.061652281
A13: =EDATE(A12,1) -> 44501 | B13: 80.637301 | C13: =(B13-B12)/B12*100 -> -1.7904511 | F13: 44470 | G13: =(Q5_CPI_Category_Levels!B12-Q5_CPI_Category_Levels!B11)/Q5_CPI_Category_Levels!B11*100 -> 0.66828676 | H13: =(Q5_CPI_Category_Levels!C12-Q5_CPI_Category_Levels!C11)/Q5_CPI_Category_Levels!C11*100 -> 0.61236987 | I13: =(Q5_CPI_Category_Levels!D12-Q5_CPI_Category_Levels!D11)/Q5_CPI_Category_Levels!D11*100 -> 0.12217471 | J13: =(Q5_CPI_Category_Levels!E12-Q5_CPI_Category_Levels!E11)/Q5_CPI_Category_Levels!E11*100 -> -0.92592593 | K13: =(Q5_CPI_Category_Levels!F12-Q5_CPI_Category_Levels!F11)/Q5_CPI_Category_Levels!F11*100 -> 0.643915 | L13: =(Q5_CPI_Category_Levels!G12-Q5_CPI_Category_Levels!G11)/Q5_CPI_Category_Levels!G11*100 -> -0.63816209 | M13: =(Q5_CPI_Category_Levels!H12-Q5_CPI_Category_Levels!H11)/Q5_CPI_Category_Levels!H11*100 -> 0.98400984 | N13: =(Q5_CPI_Category_Levels!I12-Q5_CPI_Category_Levels!I11)/Q5_CPI_Category_Levels!I11*100 -> 0.41567696 | ... AC13: =(Q5_CPI_Category_Levels!X12-Q5_CPI_Category_Levels!X11)/Q5_CPI_Category_Levels!X11*100 -> 14.171288
A14: =EDATE(A13,1) -> 44531 | B14: 73.298824 | C14: =(B14-B13)/B13*100 -> -9.1005991 | F14: 44501 | G14: =(Q5_CPI_Category_Levels!B13-Q5_CPI_Category_Levels!B12)/Q5_CPI_Category_Levels!B12*100 -> 0.90525045 | H14: =(Q5_CPI_Category_Levels!C13-Q5_CPI_Category_Levels!C12)/Q5_CPI_Category_Levels!C12*100 -> 0.91296409 | I14: =(Q5_CPI_Category_Levels!D13-Q5_CPI_Category_Levels!D12)/Q5_CPI_Category_Levels!D12*100 -> 0.24405125 | J14: =(Q5_CPI_Category_Levels!E13-Q5_CPI_Category_Levels!E12)/Q5_CPI_Category_Levels!E12*100 -> 1.0514019 | K14: =(Q5_CPI_Category_Levels!F13-Q5_CPI_Category_Levels!F12)/Q5_CPI_Category_Levels!F12*100 -> 0.70377479 | L14: =(Q5_CPI_Category_Levels!G13-Q5_CPI_Category_Levels!G12)/Q5_CPI_Category_Levels!G12*100 -> 0.51380861 | M14: =(Q5_CPI_Category_Levels!H13-Q5_CPI_Category_Levels!H12)/Q5_CPI_Category_Levels!H12*100 -> -0.18270402 | N14: =(Q5_CPI_Category_Levels!I13-Q5_CPI_Category_Levels!I12)/Q5_CPI_Category_Levels!I12*100 -> 0.47309284 | ... AC14: =(Q5_CPI_Category_Levels!X13-Q5_CPI_Category_Levels!X12)/Q5_CPI_Category_Levels!X12*100 -> 7.5013492
A15: =EDATE(A14,1) -> 44562 | B15: 84.666319 | C15: =(B15-B14)/B14*100 -> 15.508428 | F15: 44531 | G15: =(Q5_CPI_Category_Levels!B14-Q5_CPI_Category_Levels!B13)/Q5_CPI_Category_Levels!B13*100 -> 0.77751196 | H15: =(Q5_CPI_Category_Levels!C14-Q5_CPI_Category_Levels!C13)/Q5_CPI_Category_Levels!C13*100 -> 0.72376357 | I15: =(Q5_CPI_Category_Levels!D14-Q5_CPI_Category_Levels!D13)/Q5_CPI_Category_Levels!D13*100 -> 0.060864273 | J15: =(Q5_CPI_Category_Levels!E14-Q5_CPI_Category_Levels!E13)/Q5_CPI_Category_Levels!E13*100 -> 2.8323699 | K15: =(Q5_CPI_Category_Levels!F14-Q5_CPI_Category_Levels!F13)/Q5_CPI_Category_Levels!F13*100 -> 0.82592122 | L15: =(Q5_CPI_Category_Levels!G14-Q5_CPI_Category_Levels!G13)/Q5_CPI_Category_Levels!G13*100 -> -1.0223642 | M15: =(Q5_CPI_Category_Levels!H14-Q5_CPI_Category_Levels!H13)/Q5_CPI_Category_Levels!H13*100 -> 0.12202563 | N15: =(Q5_CPI_Category_Levels!I14-Q5_CPI_Category_Levels!I13)/Q5_CPI_Category_Levels!I13*100 -> 0.41200706 | ... AC15: =(Q5_CPI_Category_Levels!X14-Q5_CPI_Category_Levels!X13)/Q5_CPI_Category_Levels!X13*100 -> -5.4718876
... A31: =EDATE(A30,1) -> 45047 | B31: 74.981548 | C31: =(B31-B30)/B30*100 -> -10.475522 | F31: 45017 | G31: =(Q5_CPI_Category_Levels!B30-Q5_CPI_Category_Levels!B29)/Q5_CPI_Category_Levels!B29*100 -> 0.42987641 | H31: =(Q5_CPI_Category_Levels!C30-Q5_CPI_Category_Levels!C29)/Q5_CPI_Category_Levels!C29*100 -> 0.32414911 | I31: =(Q5_CPI_Category_Levels!D30-Q5_CPI_Category_Levels!D29)/Q5_CPI_Category_Levels!D29*100 -> 0.8 | J31: =(Q5_CPI_Category_Levels!E30-Q5_CPI_Category_Levels!E29)/Q5_CPI_Category_Levels!E29*100 -> -3.196347 | K31: =(Q5_CPI_Category_Levels!F30-Q5_CPI_Category_Levels!F29)/Q5_CPI_Category_Levels!F29*100 -> 0.27979855 | L31: =(Q5_CPI_Category_Levels!G30-Q5_CPI_Category_Levels!G29)/Q5_CPI_Category_Levels!G29*100 -> 4.0117994 | M31: =(Q5_CPI_Category_Levels!H30-Q5_CPI_Category_Levels!H29)/Q5_CPI_Category_Levels!H29*100 -> -0.10995052 | N31: =(Q5_CPI_Category_Levels!I30-Q5_CPI_Category_Levels!I29)/Q5_CPI_Category_Levels!I29*100 -> 0.32537961 | ... AC31: =(Q5_CPI_Category_Levels!X30-Q5_CPI_Category_Levels!X29)/Q5_CPI_Category_Levels!X29*100 -> 1.7015707
F32: 45047 | G32: =(Q5_CPI_Category_Levels!B31-Q5_CPI_Category_Levels!B30)/Q5_CPI_Category_Levels!B30*100 -> 0.21401819 | H32: =(Q5_CPI_Category_Levels!C31-Q5_CPI_Category_Levels!C30)/Q5_CPI_Category_Levels!C30*100 -> 0.26925148 | I32: =(Q5_CPI_Category_Levels!D31-Q5_CPI_Category_Levels!D30)/Q5_CPI_Category_Levels!D30*100 -> 0.3968254 | J32: =(Q5_CPI_Category_Levels!E31-Q5_CPI_Category_Levels!E30)/Q5_CPI_Category_Levels!E30*100 -> 2.1226415 | K32: =(Q5_CPI_Category_Levels!F31-Q5_CPI_Category_Levels!F30)/Q5_CPI_Category_Levels!F30*100 -> 0.27901786 | L32: =(Q5_CPI_Category_Levels!G31-Q5_CPI_Category_Levels!G30)/Q5_CPI_Category_Levels!G30*100 -> -2.3255814 | M32: =(Q5_CPI_Category_Levels!H31-Q5_CPI_Category_Levels!H30)/Q5_CPI_Category_Levels!H30*100 -> 0.60539351 | N32: =(Q5_CPI_Category_Levels!I31-Q5_CPI_Category_Levels!I30)/Q5_CPI_Category_Levels!I30*100 -> 0.37837838 | ... AC32: =(Q5_CPI_Category_Levels!X31-Q5_CPI_Category_Levels!X30)/Q5_CPI_Category_Levels!X30*100 -> 3.6036036
F33: Correlation value | G33: =CORREL($C$4:$C$32,G4:G32) -> 0.0037531523 | H33: =CORREL($C$4:$C$32,H4:H32) -> 0.041106999 | I33: =CORREL($C$4:$C$32,I4:I32) -> -0.44827256 | J33: =CORREL($C$4:$C$32,J4:J32) -> 0.01833902 | K33: =CORREL($C$4:$C$32,K4:K32) -> 0.11581776 | L33: =CORREL($C$4:$C$32,L4:L32) -> -0.064754072 | M33: =CORREL($C$4:$C$32,M4:M32) -> 0.19016405 | N33: =CORREL($C$4:$C$32,N4:N32) -> 0.085661682 | ... AC33: =CORREL($C$4:$C$32,AC4:AC32) -> -0.35507391
D37: Category name | E37: Correlation value
D38: Milk and products | E38: -0.48085412
D39: Education | E39: -0.44827256
D40: Vegetables | E40: -0.35507391
D41: Personal care and effects | E41: -0.26623701
D42: Transport and communication | E42: 0.26531337
D43: Oils and fats | E43: 0.21970922
D44: Sugar and Confectionery | E44: -0.19289691
D45: Fuel and light | E45: 0.19016405
D46: Non-alcoholic beverages | E46: 0.17355657
D47: Housing | E47: -0.16812989
D48: Pulses and products | E48: -0.16665825
D49: Recreation and amusement | E49: 0.14679527
... D60: Clothing | E60: 0.0037531523

Sheet Q5_CPI_Category_Levels
A1: Dates | B1: Clothing | C1: Clothing and footwear | D1: Education | E1: Egg | F1: Footwear | G1: Fruits | H1: Fuel and light | I1: Health | J1: Household goods and services | K1: Housing | L1: Meat and fish | M1: Milk and products | N1: Non-alcoholic beverages | O1: Oils and fats | P1: Pan, tobacco and intoxicants | Q1: Personal care and effects | R1: Prepared meals, snacks, sweets etc. | S1: Pulses and products | T1: Recreation and amusement | U1: Spices | V1: Sugar and Confectionery | W1: Transport and communication | X1: Vegetables
A2: 44166 | B2: 155 | C2: 153.6 | D2: 159.4 | E2: 175.3 | F2: 145.4 | G2: 147.7 | H2: 144.6 | I2: 158.3 | J2: 149.7 | K2: 158.4 | L2: 191 | M2: 154.1 | N2: 149.2 | O2: 146.6 | P2: 185.4 | Q2: 157.1 | R2: 164.8 | S2: 160.2 | T2: 148.5 | U2: 163 | V2: 115.3 | W2: 140.7 | X2: 230.5
A3: 44197 | B3: 155.5 | C3: 154.2 | D3: 159.2 | E3: 175.3 | F3: 146.1 | G3: 149.6 | H3: 147.9 | I3: 159.3 | J3: 150 | K3: 157.7 | L3: 190.1 | M3: 154.1 | N3: 151.8 | O3: 150.9 | P3: 186.5 | Q3: 156.8 | R3: 165.6 | S3: 160.4 | T3: 149.6 | U3: 164 | V3: 114.6 | W3: 141.9 | X3: 194.2
A4: 44228 | B4: 157.2 | C4: 155.8 | D4: 159.5 | E4: 168.7 | F4: 147.4 | G4: 150.7 | H4: 152.4 | I4: 161.3 | J4: 150.9 | K4: 159.8 | L4: 186.5 | M4: 154.7 | N4: 155.5 | O4: 158.7 | P4: 188.3 | Q4: 155.8 | R4: 167.5 | S4: 158.8 | T4: 151.5 | U4: 164.2 | V4: 112.8 | W4: 145.1 | X4: 160
A5: 44256 | B5: 157.8 | C5: 156.4 | D5: 160.2 | E5: 163.8 | F5: 147.9 | G5: 153.7 | H5: 155.5 | I5: 161.7 | J5: 151.2 | K5: 159.9 | L5: 192.2 | M5: 154.9 | N5: 156.5 | O5: 163.9 | P5: 188.1 | Q5: 153.8 | R5: 168.2 | S5: 159.8 | T5: 152.6 | U5: 163.5 | V5: 112.6 | W5: 146.2 | X5: 149.5
A6: 44287 | B6: 158.8 | C6: 157.3 | D6: 160.3 | E6: 164.6 | F6: 148.5 | G6: 164.4 | H6: 155.6 | I6: 162.3 | J6: 151.8 | K6: 161.4 | L6: 198 | M6: 155.4 | N6: 157.6 | O6: 170.1 | P6: 188.8 | Q6: 155.4 | R6: 168.9 | S6: 161.7 | T6: 153.2 | U6: 163.9 | V6: 113.1 | W6: 146.6 | X6: 144.1
A7: 44317 | B7: 161.8 | C7: 160.4 | D7: 161.2 | E7: 170.3 | F7: 152.1 | G7: 167.1 | H7: 159.4 | I7: 165.8 | J7: 154.7 | K7: 161.6 | L7: 200.5 | M7: 156.1 | N7: 159.3 | O7: 178.7 | P7: 191.9 | Q7: 158.6 | R7: 170.4 | S7: 165.4 | T7: 155.8 | U7: 168.2 | V7: 114.8 | W7: 148.9 | X7: 147.9
A8: 44348 | B8: 162.2 | C8: 160.7 | D8: 161.7 | E8: 180.7 | F8: 151.8 | G8: 164.6 | H8: 159.8 | I8: 166.3 | J8: 154.8 | K8: 160.5 | L8: 202 | M8: 156.2 | N8: 160 | O8: 183.7 | P8: 190.8 | Q8: 158.8 | R8: 172.4 | S8: 166 | T8: 154.9 | U8: 168.5 | V8: 115.1 | W8: 150.7 | X8: 155.4
A9: 44378 | B9: 162.8 | C9: 161.4 | D9: 163.2 | E9: 182.2 | F9: 153.1 | G9: 163.9 | H9: 160.7 | I9: 167 | J9: 155.8 | K9: 161.5 | L9: 206.8 | M9: 157.5 | N9: 160.9 | O9: 182.1 | P9: 191.2 | Q9: 160.1 | R9: 172.2 | S9: 164 | T9: 155.3 | U9: 168.3 | V9: 114.5 | W9: 153.1 | X9: 164.2
A10: 44409 | B10: 164.5 | C10: 163.2 | D10: 163.8 | E10: 172.8 | F10: 155.3 | G10: 156.8 | H10: 162.6 | I10: 168.4 | J10: 157.5 | K10: 162.1 | L10: 204 | M10: 158.4 | N10: 162.7 | O10: 188 | P10: 192.1 | Q10: 160 | R10: 173.9 | S10: 164.1 | T10: 157.6 | U10: 168.8 | V10: 119.7 | W10: 154 | X10: 162.2
